<?xml version="1.0" ?>
<robot name="custom_robot">

  <!-- Base Link (fixed, no joint) -->
  <link name="base_link"/>

  <!-- Joint 1 -->
  <joint name="joint1" type="revolute">
    <parent link="base_link"/>
    <child link="link1"/>
    <origin xyz="0 0 0" rpy="0 0 0"/>      <!-- WRT Parent -->
    <axis xyz="0 0 1"/>    <!-- WRT Joint itself -->
    <limit lower="-3.141592653589793" upper="3.141592653589793" effort="100" velocity="1"/>
  </joint>

  <link name="link1">
    <visual>
      <geometry>
        <cylinder radius="0.08" length="0.01"/>
      </geometry>
       <origin xyz="0 0 0.005" rpy="0 0 0"/>
      <material name="sphere_color">
        <color rgba="1.0 .7 0. 1.0"/> <!-- Red color -->
      </material>
    </visual>
    <visual>
      <geometry>
        <cylinder radius="0.035" length="0.21"/>
      </geometry>
      <origin xyz="0 0 0.105" rpy="0 0 0"/>
      <material name="blue"/>
    </visual>
    <collision>
      <geometry>
        <cylinder radius="0.035" length="0.21"/>
      </geometry>
      <origin xyz="0 0 0.105" rpy="0 0 0"/>
    </collision>
  </link>

  <!-- Joint 2 -->
  <joint name="joint2" type="revolute">
    <parent link="link1"/>
    <child link="link2"/>
    <origin xyz="0 0 0.21" rpy="-1.57079633 0 0"/>
    <axis xyz="0 0 1"/>
    <limit lower="-3.141592653589793" upper="0" effort="100" velocity="1"/>
  </joint>
  <link name="link2">
  <!-- First part: Small cylinder -->
    <visual>
      <geometry>
        <sphere radius="0.035"/>
      </geometry>
      <material name="sphere_color">
        <color rgba="1.0 0.0 0.0 1.0"/> <!-- Red color -->
      </material>
    </visual>
  <visual>
    <geometry>
      <cylinder radius="0.035" length="0.1095"/>
    </geometry>
    <origin xyz="0 0 0.05475" rpy="0 0 0"/>
    <material name="green"/>
  </visual>

  <!-- Second part: Large cylinder (rotated to create part of the "C") -->
    <visual>
      <geometry>
        <sphere radius="0.035"/>
      </geometry>
       <origin xyz="0 0 0.107" rpy="0 0 0"/>
      <material name="sphere_color">
        <color rgba="1.0 0.0 0.0 1.0"/> <!-- Red color -->
      </material>
    </visual>
  <visual>
    <geometry>
      <cylinder radius="0.035" length="0.25"/>
    </geometry>
    <origin xyz="0.125 0 0.107" rpy="0 -1.57079633 0"/>
    <material name="green"/>
  </visual>

  <!-- Third part: Another small cylinder -->
    <visual>
      <geometry>
        <sphere radius="0.035"/>
      </geometry>
<origin xyz="0.25 0 0.107" rpy="0 0 0"/>
      <material name="sphere_color">
        <color rgba="1.0 0.0 0.0 1.0"/> <!-- Red color -->
      </material>
    </visual>
  <visual>
    <geometry>
      <cylinder radius="0.035" length="0.1095"/>
    </geometry>
    <origin xyz="0.25 0 0.05475" rpy="0 0 0"/>
    <material name="green"/>
  </visual>

  <!-- Collision part: Small cylinder (same as first part) -->
  <collision>
    <geometry>
      <cylinder radius="0.035" length="0.107"/>
    </geometry>
    <origin xyz="0 0 0.0535" rpy="0 0 0"/>
  </collision>

  <!-- Collision part: Large cylinder (same as second part) -->
  <collision>
    <geometry>
      <cylinder radius="0.035" length="0.25"/>
    </geometry>
    <origin xyz="0.125 0 0.107" rpy="0 -1.57079633 0"/>
  </collision>

  <!-- Collision part: Another small cylinder (same as third part) -->
  <collision>
    <geometry>
      <cylinder radius="0.035" length="0.107"/>
    </geometry>
    <origin xyz="0.25 0 0.0535" rpy="0 0 0"/>
  </collision>
</link>


  <!-- Joint 3 -->
  <joint name="joint3" type="revolute">
    <parent link="link2"/>
    <child link="link3"/>
    <origin xyz="0.25 0 0" rpy="0 0 0"/>
    <axis xyz="0 0 1"/>
    <limit lower="-2.6179938779914944" upper="2.6179938779914944" effort="100" velocity="1"/>
  </joint>
  <link name="link3">
    <visual>
      <geometry>
        <sphere radius="0.035"/>
      </geometry>
      <material name="sphere_color">
        <color rgba="1.0 0.0 0.0 1.0"/> <!-- Red color -->
      </material>
    </visual>
    <visual>
      <geometry>
        <cylinder radius="0.035" length="0.25"/>
      </geometry>
      <origin xyz="0.125 0 0" rpy="0 -1.57079633 0"/>
      <material name="red"/>
    </visual>
    <collision>
      <geometry>
        <cylinder radius="0.035" length="0.25"/>
      </geometry>
      <origin xyz="0.125 0 0" rpy="0 -1.57079633 0"/>
    </collision>
  </link>

  <!-- Joint 4 -->
  <joint name="joint4" type="revolute">
    <parent link="link3"/>
    <child link="link4"/>
    <origin xyz="0.25 0 0" rpy="0 0 0"/>
    <axis xyz="0 0 1"/>
    <limit lower="-4.53786" upper="1.3962634015954636" effort="100" velocity="1"/>
  </joint>

  <link name="link4">
    <visual>
      <geometry>
        <sphere radius="0.035"/>
      </geometry>
      <material name="sphere_color">
        <color rgba="1.0 0.0 0.0 1.0"/> <!-- Red color -->
      </material>
    </visual>
    <visual>
      <geometry>
        <cylinder radius="0.035" length="0.1095"/>
      </geometry>
      <origin xyz="0 0 0.05475" rpy="0 0 0"/>
      <material name="yellow"/>
    </visual>
    <collision>
      <geometry>
        <cylinder radius="0.035" length="0.1095"/>
      </geometry>
      <origin xyz="0 0 0.05475" rpy="0 0 0"/>
    </collision>
  </link>

  <!-- Joint 5 -->
  <joint name="joint5" type="revolute">
    <parent link="link4"/>
    <child link="link5"/>
    <origin xyz="0 0 0.1095" rpy="-1.57079633 0 0"/>
    <axis xyz="0 0 1"/>
    <limit lower="-2.93215" upper="2.93215" effort="100" velocity="1"/>
  </joint>
  <link name="link5">
    <visual>
      <geometry>
        <sphere radius="0.035"/>
      </geometry>
      <material name="sphere_color">
        <color rgba="1.0 0.0 0.0 1.0"/> <!-- Red color -->
      </material>
    </visual>
    <visual>
      <geometry>
        <sphere radius="0.035"/>
      </geometry>
       <origin xyz="0 0 0.107" rpy="0 -1.57079633 0"/>
      <material name="sphere_color">
        <color rgba="1.0 0.0 0.0 1.0"/> <!-- Red color -->
      </material>
    </visual>
    <visual>
      <geometry>
        <cylinder radius="0.035" length="0.107"/>
      </geometry>
      <origin xyz="0 0 0.0535" rpy="0 0 0"/>
      <material name="purple"/>
    </visual>
    <collision>
      <geometry>
        <cylinder radius="0.035" length="0.107"/>
      </geometry>
      <origin xyz="0 0 0.0535" rpy="0 0 0"/>
    </collision>
  </link>

  <!-- Joint 6 -->
  <joint name="joint6" type="revolute">
    <parent link="link5"/>
    <child link="link6"/>
    <origin xyz="0 -0.0762 0.107" rpy="1.57079633 0 0"/>
    <axis xyz="0 0 1"/>
    <limit lower="-3.03687" upper="3.03687" effort="100" velocity="1"/>
  </joint>
  <link name="link6">
    <visual>
      <geometry>
        <sphere radius="0.02"/>
      </geometry>
      <material name="sphere_color">
        <color rgba="1.0 0.0 0.0 1.0"/> <!-- Red color -->
      </material>
    </visual>
    <visual>
      <geometry>
        <cylinder radius="0.035" length="0.0762"/>
      </geometry>
      <origin xyz="0 0 -0.0381" rpy="0 0 0"/>
      <material name="cyan"/>
    </visual>
    <collision>
      <geometry>
        <cylinder radius="0.035" length="0.0762"/>
      </geometry>
      <origin xyz="0 0 -0.0381" rpy="0 0 0"/>
    </collision>
  </link>

</robot>
